ERROR:root:Command failed
Traceback (most recent call last):
  File "/home/ftg/friendly-telegram/modules/python.py", line 52, in evalcmd
    it = await meval(utils.get_args_raw(message), globals(), **await self.getattrs(message))
TypeError: meval() takes 1 positional argument but 2 were given

During handling of the above exception, another exception occurred:

Traceback (most recent call last):
  File "/home/ftg/friendly-telegram/main.py", line 129, in handle_command
    await coro
  File "/home/ftg/friendly-telegram/modules/python.py", line 55, in evalcmd
    exc = "".join(traceback.format_exception(exc[0], exc[1], exc[2].tb_next.tb_next.tb_next))
AttributeError: 'NoneType' object has no attribute 'tb_next'
ERROR:telethon.client.updates:Unhandled exception on functools.partial(<function handle_command at 0x7fd025540bf8>, <friendly-telegram.loader.Modules object at 0x7fcffa770748>, <friendly-telegram.database.frontend.Database object at 0x7fd0211e7c88>)
Traceback (most recent call last):
  File "/home/ftg/friendly-telegram/modules/python.py", line 52, in evalcmd
    it = await meval(utils.get_args_raw(message), globals(), **await self.getattrs(message))
TypeError: meval() takes 1 positional argument but 2 were given

During handling of the above exception, another exception occurred:

Traceback (most recent call last):
  File "/home/eren/.local/lib/python3.7/site-packages/telethon/client/updates.py", line 422, in _dispatch_update
    await callback(event)
  File "/home/ftg/friendly-telegram/main.py", line 137, in handle_command
    raise e
  File "/home/ftg/friendly-telegram/main.py", line 129, in handle_command
    await coro
  File "/home/ftg/friendly-telegram/modules/python.py", line 55, in evalcmd
    exc = "".join(traceback.format_exception(exc[0], exc[1], exc[2].tb_next.tb_next.tb_next))
AttributeError: 'NoneType' object has no attribute 'tb_next'